[2023-05-05 18:20:37,853] {taskinstance.py:1037} INFO - Dependencies all met for <TaskInstance: PredictingPipeline.request_predictions_step scheduled__2023-05-04T18:20:37.165834+00:00 [queued]>
[2023-05-05 18:20:37,859] {taskinstance.py:1037} INFO - Dependencies all met for <TaskInstance: PredictingPipeline.request_predictions_step scheduled__2023-05-04T18:20:37.165834+00:00 [queued]>
[2023-05-05 18:20:37,859] {taskinstance.py:1243} INFO - 
--------------------------------------------------------------------------------
[2023-05-05 18:20:37,859] {taskinstance.py:1244} INFO - Starting attempt 1 of 1
[2023-05-05 18:20:37,859] {taskinstance.py:1245} INFO - 
--------------------------------------------------------------------------------
[2023-05-05 18:20:37,867] {taskinstance.py:1264} INFO - Executing <Task(PredictionResquestsOperator): request_predictions_step> on 2023-05-04 18:20:37.165834+00:00
[2023-05-05 18:20:37,870] {standard_task_runner.py:52} INFO - Started process 56954 to run task
[2023-05-05 18:20:37,872] {standard_task_runner.py:76} INFO - Running: ['***', 'tasks', 'run', 'PredictingPipeline', 'request_predictions_step', 'scheduled__2023-05-04T18:20:37.165834+00:00', '--job-id', '37', '--raw', '--subdir', 'DAGS_FOLDER/predict_pipeline.py', '--cfg-path', '/tmp/tmp7klyg5nm', '--error-file', '/tmp/tmpxd9o56op']
[2023-05-05 18:20:37,873] {standard_task_runner.py:77} INFO - Job 37: Subtask request_predictions_step
[2023-05-05 18:20:37,904] {logging_mixin.py:109} INFO - Running <TaskInstance: PredictingPipeline.request_predictions_step scheduled__2023-05-04T18:20:37.165834+00:00 [running]> on host bd19d9975108
[2023-05-05 18:20:37,928] {logging_mixin.py:109} WARNING - /home/***/.local/lib/python3.7/site-packages/***/utils/context.py:156 AirflowContextDeprecationWarning: Accessing 'execution_date' from the template is deprecated and will be removed in a future version. Please use 'data_interval_start' or 'logical_date' instead.
[2023-05-05 18:20:37,940] {taskinstance.py:1431} INFO - Exporting the following env vars:
AIRFLOW_CTX_DAG_OWNER=***
AIRFLOW_CTX_DAG_ID=PredictingPipeline
AIRFLOW_CTX_TASK_ID=request_predictions_step
AIRFLOW_CTX_EXECUTION_DATE=2023-05-04T18:20:37.165834+00:00
AIRFLOW_CTX_DAG_RUN_ID=scheduled__2023-05-04T18:20:37.165834+00:00
[2023-05-05 18:20:37,951] {connectionpool.py:811} WARNING - Retrying (Retry(total=4, connect=None, read=None, redirect=None, status=None)) after connection broken by 'NewConnectionError('<urllib3.connection.HTTPConnection object at 0x7f8bc9fe0210>: Failed to establish a new connection: [Errno -2] Name or service not known')': /ping
[2023-05-05 18:20:39,959] {connectionpool.py:811} WARNING - Retrying (Retry(total=3, connect=None, read=None, redirect=None, status=None)) after connection broken by 'NewConnectionError('<urllib3.connection.HTTPConnection object at 0x7f8beb7493d0>: Failed to establish a new connection: [Errno -2] Name or service not known')': /ping
[2023-05-05 18:20:43,973] {connectionpool.py:811} WARNING - Retrying (Retry(total=2, connect=None, read=None, redirect=None, status=None)) after connection broken by 'NewConnectionError('<urllib3.connection.HTTPConnection object at 0x7f8bc9fec790>: Failed to establish a new connection: [Errno -2] Name or service not known')': /ping
[2023-05-05 18:20:51,995] {connectionpool.py:811} WARNING - Retrying (Retry(total=1, connect=None, read=None, redirect=None, status=None)) after connection broken by 'NewConnectionError('<urllib3.connection.HTTPConnection object at 0x7f8bc9fecd90>: Failed to establish a new connection: [Errno -2] Name or service not known')': /ping
[2023-05-05 18:21:08,024] {connectionpool.py:811} WARNING - Retrying (Retry(total=0, connect=None, read=None, redirect=None, status=None)) after connection broken by 'NewConnectionError('<urllib3.connection.HTTPConnection object at 0x7f8be32923d0>: Failed to establish a new connection: [Errno -2] Name or service not known')': /ping
[2023-05-05 18:21:08,035] {taskinstance.py:1718} ERROR - Task failed with exception
Traceback (most recent call last):
  File "/home/airflow/.local/lib/python3.7/site-packages/urllib3/connection.py", line 175, in _new_conn
    (self._dns_host, self.port), self.timeout, **extra_kw
  File "/home/airflow/.local/lib/python3.7/site-packages/urllib3/util/connection.py", line 72, in create_connection
    for res in socket.getaddrinfo(host, port, family, socket.SOCK_STREAM):
  File "/usr/local/lib/python3.7/socket.py", line 752, in getaddrinfo
    for res in _socket.getaddrinfo(host, port, family, type, proto, flags):
socket.gaierror: [Errno -2] Name or service not known

During handling of the above exception, another exception occurred:

Traceback (most recent call last):
  File "/home/airflow/.local/lib/python3.7/site-packages/urllib3/connectionpool.py", line 710, in urlopen
    chunked=chunked,
  File "/home/airflow/.local/lib/python3.7/site-packages/urllib3/connectionpool.py", line 398, in _make_request
    conn.request(method, url, **httplib_request_kw)
  File "/home/airflow/.local/lib/python3.7/site-packages/urllib3/connection.py", line 239, in request
    super(HTTPConnection, self).request(method, url, body=body, headers=headers)
  File "/usr/local/lib/python3.7/http/client.py", line 1281, in request
    self._send_request(method, url, body, headers, encode_chunked)
  File "/usr/local/lib/python3.7/http/client.py", line 1327, in _send_request
    self.endheaders(body, encode_chunked=encode_chunked)
  File "/usr/local/lib/python3.7/http/client.py", line 1276, in endheaders
    self._send_output(message_body, encode_chunked=encode_chunked)
  File "/usr/local/lib/python3.7/http/client.py", line 1036, in _send_output
    self.send(msg)
  File "/usr/local/lib/python3.7/http/client.py", line 976, in send
    self.connect()
  File "/home/airflow/.local/lib/python3.7/site-packages/urllib3/connection.py", line 205, in connect
    conn = self._new_conn()
  File "/home/airflow/.local/lib/python3.7/site-packages/urllib3/connection.py", line 187, in _new_conn
    self, "Failed to establish a new connection: %s" % e
urllib3.exceptions.NewConnectionError: <urllib3.connection.HTTPConnection object at 0x7f8be32929d0>: Failed to establish a new connection: [Errno -2] Name or service not known

During handling of the above exception, another exception occurred:

Traceback (most recent call last):
  File "/home/airflow/.local/lib/python3.7/site-packages/requests/adapters.py", line 450, in send
    timeout=timeout
  File "/home/airflow/.local/lib/python3.7/site-packages/urllib3/connectionpool.py", line 826, in urlopen
    **response_kw
  File "/home/airflow/.local/lib/python3.7/site-packages/urllib3/connectionpool.py", line 826, in urlopen
    **response_kw
  File "/home/airflow/.local/lib/python3.7/site-packages/urllib3/connectionpool.py", line 826, in urlopen
    **response_kw
  [Previous line repeated 2 more times]
  File "/home/airflow/.local/lib/python3.7/site-packages/urllib3/connectionpool.py", line 786, in urlopen
    method, url, error=e, _pool=self, _stacktrace=sys.exc_info()[2]
  File "/home/airflow/.local/lib/python3.7/site-packages/urllib3/util/retry.py", line 592, in increment
    raise MaxRetryError(_pool, url, error or ResponseError(cause))
urllib3.exceptions.MaxRetryError: HTTPConnectionPool(host='mlproject', port=8000): Max retries exceeded with url: /ping (Caused by NewConnectionError('<urllib3.connection.HTTPConnection object at 0x7f8be32929d0>: Failed to establish a new connection: [Errno -2] Name or service not known'))

During handling of the above exception, another exception occurred:

Traceback (most recent call last):
  File "/home/airflow/.local/lib/python3.7/site-packages/airflow/models/taskinstance.py", line 1334, in _run_raw_task
    self._execute_task_with_callbacks(context)
  File "/home/airflow/.local/lib/python3.7/site-packages/airflow/models/taskinstance.py", line 1460, in _execute_task_with_callbacks
    result = self._execute_task(context, self.task)
  File "/home/airflow/.local/lib/python3.7/site-packages/airflow/models/taskinstance.py", line 1516, in _execute_task
    result = execute_callable(context=context)
  File "/opt/airflow/plugins/operators/prediction_resquests_operator.py", line 53, in execute
    self._health_check()
  File "/opt/airflow/plugins/operators/prediction_resquests_operator.py", line 45, in _health_check
    if not session.get(self.ping_url).ok:
  File "/home/airflow/.local/lib/python3.7/site-packages/requests/sessions.py", line 542, in get
    return self.request('GET', url, **kwargs)
  File "/home/airflow/.local/lib/python3.7/site-packages/requests/sessions.py", line 529, in request
    resp = self.send(prep, **send_kwargs)
  File "/home/airflow/.local/lib/python3.7/site-packages/requests/sessions.py", line 645, in send
    r = adapter.send(request, **kwargs)
  File "/home/airflow/.local/lib/python3.7/site-packages/requests/adapters.py", line 519, in send
    raise ConnectionError(e, request=request)
requests.exceptions.ConnectionError: HTTPConnectionPool(host='mlproject', port=8000): Max retries exceeded with url: /ping (Caused by NewConnectionError('<urllib3.connection.HTTPConnection object at 0x7f8be32929d0>: Failed to establish a new connection: [Errno -2] Name or service not known'))
[2023-05-05 18:21:08,059] {taskinstance.py:1282} INFO - Marking task as FAILED. dag_id=PredictingPipeline, task_id=request_predictions_step, execution_date=20230504T182037, start_date=20230505T182037, end_date=20230505T182108
[2023-05-05 18:21:08,074] {standard_task_runner.py:92} ERROR - Failed to execute job 37 for task request_predictions_step
Traceback (most recent call last):
  File "/home/airflow/.local/lib/python3.7/site-packages/urllib3/connection.py", line 175, in _new_conn
    (self._dns_host, self.port), self.timeout, **extra_kw
  File "/home/airflow/.local/lib/python3.7/site-packages/urllib3/util/connection.py", line 72, in create_connection
    for res in socket.getaddrinfo(host, port, family, socket.SOCK_STREAM):
  File "/usr/local/lib/python3.7/socket.py", line 752, in getaddrinfo
    for res in _socket.getaddrinfo(host, port, family, type, proto, flags):
socket.gaierror: [Errno -2] Name or service not known

During handling of the above exception, another exception occurred:

Traceback (most recent call last):
  File "/home/airflow/.local/lib/python3.7/site-packages/urllib3/connectionpool.py", line 710, in urlopen
    chunked=chunked,
  File "/home/airflow/.local/lib/python3.7/site-packages/urllib3/connectionpool.py", line 398, in _make_request
    conn.request(method, url, **httplib_request_kw)
  File "/home/airflow/.local/lib/python3.7/site-packages/urllib3/connection.py", line 239, in request
    super(HTTPConnection, self).request(method, url, body=body, headers=headers)
  File "/usr/local/lib/python3.7/http/client.py", line 1281, in request
    self._send_request(method, url, body, headers, encode_chunked)
  File "/usr/local/lib/python3.7/http/client.py", line 1327, in _send_request
    self.endheaders(body, encode_chunked=encode_chunked)
  File "/usr/local/lib/python3.7/http/client.py", line 1276, in endheaders
    self._send_output(message_body, encode_chunked=encode_chunked)
  File "/usr/local/lib/python3.7/http/client.py", line 1036, in _send_output
    self.send(msg)
  File "/usr/local/lib/python3.7/http/client.py", line 976, in send
    self.connect()
  File "/home/airflow/.local/lib/python3.7/site-packages/urllib3/connection.py", line 205, in connect
    conn = self._new_conn()
  File "/home/airflow/.local/lib/python3.7/site-packages/urllib3/connection.py", line 187, in _new_conn
    self, "Failed to establish a new connection: %s" % e
urllib3.exceptions.NewConnectionError: <urllib3.connection.HTTPConnection object at 0x7f8be32929d0>: Failed to establish a new connection: [Errno -2] Name or service not known

During handling of the above exception, another exception occurred:

Traceback (most recent call last):
  File "/home/airflow/.local/lib/python3.7/site-packages/requests/adapters.py", line 450, in send
    timeout=timeout
  File "/home/airflow/.local/lib/python3.7/site-packages/urllib3/connectionpool.py", line 826, in urlopen
    **response_kw
  File "/home/airflow/.local/lib/python3.7/site-packages/urllib3/connectionpool.py", line 826, in urlopen
    **response_kw
  File "/home/airflow/.local/lib/python3.7/site-packages/urllib3/connectionpool.py", line 826, in urlopen
    **response_kw
  [Previous line repeated 2 more times]
  File "/home/airflow/.local/lib/python3.7/site-packages/urllib3/connectionpool.py", line 786, in urlopen
    method, url, error=e, _pool=self, _stacktrace=sys.exc_info()[2]
  File "/home/airflow/.local/lib/python3.7/site-packages/urllib3/util/retry.py", line 592, in increment
    raise MaxRetryError(_pool, url, error or ResponseError(cause))
urllib3.exceptions.MaxRetryError: HTTPConnectionPool(host='mlproject', port=8000): Max retries exceeded with url: /ping (Caused by NewConnectionError('<urllib3.connection.HTTPConnection object at 0x7f8be32929d0>: Failed to establish a new connection: [Errno -2] Name or service not known'))

During handling of the above exception, another exception occurred:

Traceback (most recent call last):
  File "/home/airflow/.local/lib/python3.7/site-packages/airflow/task/task_runner/standard_task_runner.py", line 85, in _start_by_fork
    args.func(args, dag=self.dag)
  File "/home/airflow/.local/lib/python3.7/site-packages/airflow/cli/cli_parser.py", line 48, in command
    return func(*args, **kwargs)
  File "/home/airflow/.local/lib/python3.7/site-packages/airflow/utils/cli.py", line 92, in wrapper
    return f(*args, **kwargs)
  File "/home/airflow/.local/lib/python3.7/site-packages/airflow/cli/commands/task_command.py", line 298, in task_run
    _run_task_by_selected_method(args, dag, ti)
  File "/home/airflow/.local/lib/python3.7/site-packages/airflow/cli/commands/task_command.py", line 107, in _run_task_by_selected_method
    _run_raw_task(args, ti)
  File "/home/airflow/.local/lib/python3.7/site-packages/airflow/cli/commands/task_command.py", line 184, in _run_raw_task
    error_file=args.error_file,
  File "/home/airflow/.local/lib/python3.7/site-packages/airflow/utils/session.py", line 70, in wrapper
    return func(*args, session=session, **kwargs)
  File "/home/airflow/.local/lib/python3.7/site-packages/airflow/models/taskinstance.py", line 1334, in _run_raw_task
    self._execute_task_with_callbacks(context)
  File "/home/airflow/.local/lib/python3.7/site-packages/airflow/models/taskinstance.py", line 1460, in _execute_task_with_callbacks
    result = self._execute_task(context, self.task)
  File "/home/airflow/.local/lib/python3.7/site-packages/airflow/models/taskinstance.py", line 1516, in _execute_task
    result = execute_callable(context=context)
  File "/opt/airflow/plugins/operators/prediction_resquests_operator.py", line 53, in execute
    self._health_check()
  File "/opt/airflow/plugins/operators/prediction_resquests_operator.py", line 45, in _health_check
    if not session.get(self.ping_url).ok:
  File "/home/airflow/.local/lib/python3.7/site-packages/requests/sessions.py", line 542, in get
    return self.request('GET', url, **kwargs)
  File "/home/airflow/.local/lib/python3.7/site-packages/requests/sessions.py", line 529, in request
    resp = self.send(prep, **send_kwargs)
  File "/home/airflow/.local/lib/python3.7/site-packages/requests/sessions.py", line 645, in send
    r = adapter.send(request, **kwargs)
  File "/home/airflow/.local/lib/python3.7/site-packages/requests/adapters.py", line 519, in send
    raise ConnectionError(e, request=request)
requests.exceptions.ConnectionError: HTTPConnectionPool(host='mlproject', port=8000): Max retries exceeded with url: /ping (Caused by NewConnectionError('<urllib3.connection.HTTPConnection object at 0x7f8be32929d0>: Failed to establish a new connection: [Errno -2] Name or service not known'))
[2023-05-05 18:21:08,088] {local_task_job.py:154} INFO - Task exited with return code 1
[2023-05-05 18:21:08,129] {local_task_job.py:264} INFO - 0 downstream tasks scheduled from follow-on schedule check
