[2023-05-04 18:39:37,275] {taskinstance.py:1037} INFO - Dependencies all met for <TaskInstance: PredictingPipeline.predict_service_step manual__2023-05-04T18:39:36.530323+00:00 [queued]>
[2023-05-04 18:39:37,281] {taskinstance.py:1037} INFO - Dependencies all met for <TaskInstance: PredictingPipeline.predict_service_step manual__2023-05-04T18:39:36.530323+00:00 [queued]>
[2023-05-04 18:39:37,282] {taskinstance.py:1243} INFO - 
--------------------------------------------------------------------------------
[2023-05-04 18:39:37,282] {taskinstance.py:1244} INFO - Starting attempt 1 of 1
[2023-05-04 18:39:37,282] {taskinstance.py:1245} INFO - 
--------------------------------------------------------------------------------
[2023-05-04 18:39:37,291] {taskinstance.py:1264} INFO - Executing <Task(DockerOperatorWithExposedPorts): predict_service_step> on 2023-05-04 18:39:36.530323+00:00
[2023-05-04 18:39:37,295] {standard_task_runner.py:52} INFO - Started process 318 to run task
[2023-05-04 18:39:37,297] {standard_task_runner.py:76} INFO - Running: ['***', 'tasks', 'run', 'PredictingPipeline', 'predict_service_step', 'manual__2023-05-04T18:39:36.530323+00:00', '--job-id', '40', '--raw', '--subdir', 'DAGS_FOLDER/predict_pipeline.py', '--cfg-path', '/tmp/tmp117hu9hb', '--error-file', '/tmp/tmpd2vf0axd']
[2023-05-04 18:39:37,298] {standard_task_runner.py:77} INFO - Job 40: Subtask predict_service_step
[2023-05-04 18:39:37,336] {logging_mixin.py:109} INFO - Running <TaskInstance: PredictingPipeline.predict_service_step manual__2023-05-04T18:39:36.530323+00:00 [running]> on host 62f67588e447
[2023-05-04 18:39:37,380] {taskinstance.py:1431} INFO - Exporting the following env vars:
AIRFLOW_CTX_DAG_OWNER=***
AIRFLOW_CTX_DAG_ID=PredictingPipeline
AIRFLOW_CTX_TASK_ID=predict_service_step
AIRFLOW_CTX_EXECUTION_DATE=2023-05-04T18:39:36.530323+00:00
AIRFLOW_CTX_DAG_RUN_ID=manual__2023-05-04T18:39:36.530323+00:00
[2023-05-04 18:39:37,392] {docker.py:236} INFO - Starting docker container from image ml_project
[2023-05-04 18:39:37,394] {docker.py:247} WARNING - Using remote engine or docker-in-docker and mounting temporary volume from host is not supported. Falling back to `mount_tmp_dir=False` mode. You can set `mount_tmp_dir` parameter to False to disable mounting and remove the warning
[2023-05-04 18:39:37,396] {taskinstance.py:1718} ERROR - Task failed with exception
Traceback (most recent call last):
  File "/home/airflow/.local/lib/python3.7/site-packages/docker/api/client.py", line 268, in _raise_for_status
    response.raise_for_status()
  File "/home/airflow/.local/lib/python3.7/site-packages/requests/models.py", line 960, in raise_for_status
    raise HTTPError(http_error_msg, response=self)
requests.exceptions.HTTPError: 400 Client Error: Bad Request for url: http+docker://localhost/v1.42/containers/create?name=mlproject

During handling of the above exception, another exception occurred:

Traceback (most recent call last):
  File "/home/airflow/.local/lib/python3.7/site-packages/airflow/providers/docker/operators/docker.py", line 243, in _run_image
    return self._run_image_with_mounts(self.mounts + [tmp_mount], add_tmp_variable=True)
  File "/opt/airflow/plugins/operators/docker_operator_with_exposed_ports.py", line 76, in _run_image_with_mounts
    tty=self.tty,
  File "/home/airflow/.local/lib/python3.7/site-packages/docker/api/container.py", line 428, in create_container
    return self.create_container_from_config(config, name)
  File "/home/airflow/.local/lib/python3.7/site-packages/docker/api/container.py", line 439, in create_container_from_config
    return self._result(res, True)
  File "/home/airflow/.local/lib/python3.7/site-packages/docker/api/client.py", line 274, in _result
    self._raise_for_status(response)
  File "/home/airflow/.local/lib/python3.7/site-packages/docker/api/client.py", line 270, in _raise_for_status
    raise create_api_error_from_http_exception(e)
  File "/home/airflow/.local/lib/python3.7/site-packages/docker/errors.py", line 31, in create_api_error_from_http_exception
    raise cls(e, response=response, explanation=explanation)
docker.errors.APIError: 400 Client Error for http+docker://localhost/v1.42/containers/create?name=mlproject: Bad Request ("invalid mount config for type "bind": bind source path does not exist: /tmp/airflowtmpr_qrkzky")

During handling of the above exception, another exception occurred:

Traceback (most recent call last):
  File "/home/airflow/.local/lib/python3.7/site-packages/docker/api/client.py", line 268, in _raise_for_status
    response.raise_for_status()
  File "/home/airflow/.local/lib/python3.7/site-packages/requests/models.py", line 960, in raise_for_status
    raise HTTPError(http_error_msg, response=self)
requests.exceptions.HTTPError: 409 Client Error: Conflict for url: http+docker://localhost/v1.42/containers/create?name=mlproject

During handling of the above exception, another exception occurred:

Traceback (most recent call last):
  File "/home/airflow/.local/lib/python3.7/site-packages/airflow/models/taskinstance.py", line 1334, in _run_raw_task
    self._execute_task_with_callbacks(context)
  File "/home/airflow/.local/lib/python3.7/site-packages/airflow/models/taskinstance.py", line 1460, in _execute_task_with_callbacks
    result = self._execute_task(context, self.task)
  File "/home/airflow/.local/lib/python3.7/site-packages/airflow/models/taskinstance.py", line 1516, in _execute_task
    result = execute_callable(context=context)
  File "/home/airflow/.local/lib/python3.7/site-packages/airflow/providers/docker/operators/docker.py", line 376, in execute
    return self._run_image()
  File "/home/airflow/.local/lib/python3.7/site-packages/airflow/providers/docker/operators/docker.py", line 252, in _run_image
    return self._run_image_with_mounts(self.mounts, add_tmp_variable=False)
  File "/opt/airflow/plugins/operators/docker_operator_with_exposed_ports.py", line 76, in _run_image_with_mounts
    tty=self.tty,
  File "/home/airflow/.local/lib/python3.7/site-packages/docker/api/container.py", line 428, in create_container
    return self.create_container_from_config(config, name)
  File "/home/airflow/.local/lib/python3.7/site-packages/docker/api/container.py", line 439, in create_container_from_config
    return self._result(res, True)
  File "/home/airflow/.local/lib/python3.7/site-packages/docker/api/client.py", line 274, in _result
    self._raise_for_status(response)
  File "/home/airflow/.local/lib/python3.7/site-packages/docker/api/client.py", line 270, in _raise_for_status
    raise create_api_error_from_http_exception(e)
  File "/home/airflow/.local/lib/python3.7/site-packages/docker/errors.py", line 31, in create_api_error_from_http_exception
    raise cls(e, response=response, explanation=explanation)
docker.errors.APIError: 409 Client Error for http+docker://localhost/v1.42/containers/create?name=mlproject: Conflict ("Conflict. The container name "/mlproject" is already in use by container "e6309fd6eae1afc5d97f623f408987137d48b06f60c61874389f61ed36c72d17". You have to remove (or rename) that container to be able to reuse that name.")
[2023-05-04 18:39:37,404] {taskinstance.py:1282} INFO - Marking task as FAILED. dag_id=PredictingPipeline, task_id=predict_service_step, execution_date=20230504T183936, start_date=20230504T183937, end_date=20230504T183937
[2023-05-04 18:39:37,412] {standard_task_runner.py:92} ERROR - Failed to execute job 40 for task predict_service_step
Traceback (most recent call last):
  File "/home/airflow/.local/lib/python3.7/site-packages/docker/api/client.py", line 268, in _raise_for_status
    response.raise_for_status()
  File "/home/airflow/.local/lib/python3.7/site-packages/requests/models.py", line 960, in raise_for_status
    raise HTTPError(http_error_msg, response=self)
requests.exceptions.HTTPError: 400 Client Error: Bad Request for url: http+docker://localhost/v1.42/containers/create?name=mlproject

During handling of the above exception, another exception occurred:

Traceback (most recent call last):
  File "/home/airflow/.local/lib/python3.7/site-packages/airflow/providers/docker/operators/docker.py", line 243, in _run_image
    return self._run_image_with_mounts(self.mounts + [tmp_mount], add_tmp_variable=True)
  File "/opt/airflow/plugins/operators/docker_operator_with_exposed_ports.py", line 76, in _run_image_with_mounts
    tty=self.tty,
  File "/home/airflow/.local/lib/python3.7/site-packages/docker/api/container.py", line 428, in create_container
    return self.create_container_from_config(config, name)
  File "/home/airflow/.local/lib/python3.7/site-packages/docker/api/container.py", line 439, in create_container_from_config
    return self._result(res, True)
  File "/home/airflow/.local/lib/python3.7/site-packages/docker/api/client.py", line 274, in _result
    self._raise_for_status(response)
  File "/home/airflow/.local/lib/python3.7/site-packages/docker/api/client.py", line 270, in _raise_for_status
    raise create_api_error_from_http_exception(e)
  File "/home/airflow/.local/lib/python3.7/site-packages/docker/errors.py", line 31, in create_api_error_from_http_exception
    raise cls(e, response=response, explanation=explanation)
docker.errors.APIError: 400 Client Error for http+docker://localhost/v1.42/containers/create?name=mlproject: Bad Request ("invalid mount config for type "bind": bind source path does not exist: /tmp/airflowtmpr_qrkzky")

During handling of the above exception, another exception occurred:

Traceback (most recent call last):
  File "/home/airflow/.local/lib/python3.7/site-packages/docker/api/client.py", line 268, in _raise_for_status
    response.raise_for_status()
  File "/home/airflow/.local/lib/python3.7/site-packages/requests/models.py", line 960, in raise_for_status
    raise HTTPError(http_error_msg, response=self)
requests.exceptions.HTTPError: 409 Client Error: Conflict for url: http+docker://localhost/v1.42/containers/create?name=mlproject

During handling of the above exception, another exception occurred:

Traceback (most recent call last):
  File "/home/airflow/.local/lib/python3.7/site-packages/airflow/task/task_runner/standard_task_runner.py", line 85, in _start_by_fork
    args.func(args, dag=self.dag)
  File "/home/airflow/.local/lib/python3.7/site-packages/airflow/cli/cli_parser.py", line 48, in command
    return func(*args, **kwargs)
  File "/home/airflow/.local/lib/python3.7/site-packages/airflow/utils/cli.py", line 92, in wrapper
    return f(*args, **kwargs)
  File "/home/airflow/.local/lib/python3.7/site-packages/airflow/cli/commands/task_command.py", line 298, in task_run
    _run_task_by_selected_method(args, dag, ti)
  File "/home/airflow/.local/lib/python3.7/site-packages/airflow/cli/commands/task_command.py", line 107, in _run_task_by_selected_method
    _run_raw_task(args, ti)
  File "/home/airflow/.local/lib/python3.7/site-packages/airflow/cli/commands/task_command.py", line 184, in _run_raw_task
    error_file=args.error_file,
  File "/home/airflow/.local/lib/python3.7/site-packages/airflow/utils/session.py", line 70, in wrapper
    return func(*args, session=session, **kwargs)
  File "/home/airflow/.local/lib/python3.7/site-packages/airflow/models/taskinstance.py", line 1334, in _run_raw_task
    self._execute_task_with_callbacks(context)
  File "/home/airflow/.local/lib/python3.7/site-packages/airflow/models/taskinstance.py", line 1460, in _execute_task_with_callbacks
    result = self._execute_task(context, self.task)
  File "/home/airflow/.local/lib/python3.7/site-packages/airflow/models/taskinstance.py", line 1516, in _execute_task
    result = execute_callable(context=context)
  File "/home/airflow/.local/lib/python3.7/site-packages/airflow/providers/docker/operators/docker.py", line 376, in execute
    return self._run_image()
  File "/home/airflow/.local/lib/python3.7/site-packages/airflow/providers/docker/operators/docker.py", line 252, in _run_image
    return self._run_image_with_mounts(self.mounts, add_tmp_variable=False)
  File "/opt/airflow/plugins/operators/docker_operator_with_exposed_ports.py", line 76, in _run_image_with_mounts
    tty=self.tty,
  File "/home/airflow/.local/lib/python3.7/site-packages/docker/api/container.py", line 428, in create_container
    return self.create_container_from_config(config, name)
  File "/home/airflow/.local/lib/python3.7/site-packages/docker/api/container.py", line 439, in create_container_from_config
    return self._result(res, True)
  File "/home/airflow/.local/lib/python3.7/site-packages/docker/api/client.py", line 274, in _result
    self._raise_for_status(response)
  File "/home/airflow/.local/lib/python3.7/site-packages/docker/api/client.py", line 270, in _raise_for_status
    raise create_api_error_from_http_exception(e)
  File "/home/airflow/.local/lib/python3.7/site-packages/docker/errors.py", line 31, in create_api_error_from_http_exception
    raise cls(e, response=response, explanation=explanation)
docker.errors.APIError: 409 Client Error for http+docker://localhost/v1.42/containers/create?name=mlproject: Conflict ("Conflict. The container name "/mlproject" is already in use by container "e6309fd6eae1afc5d97f623f408987137d48b06f60c61874389f61ed36c72d17". You have to remove (or rename) that container to be able to reuse that name.")
[2023-05-04 18:39:37,430] {local_task_job.py:154} INFO - Task exited with return code 1
[2023-05-04 18:39:37,455] {local_task_job.py:264} INFO - 0 downstream tasks scheduled from follow-on schedule check
