[2023-05-05 18:20:37,835] {taskinstance.py:1037} INFO - Dependencies all met for <TaskInstance: PredictingPipeline.predict_service_step scheduled__2023-05-04T18:20:37.165834+00:00 [queued]>
[2023-05-05 18:20:37,841] {taskinstance.py:1037} INFO - Dependencies all met for <TaskInstance: PredictingPipeline.predict_service_step scheduled__2023-05-04T18:20:37.165834+00:00 [queued]>
[2023-05-05 18:20:37,841] {taskinstance.py:1243} INFO - 
--------------------------------------------------------------------------------
[2023-05-05 18:20:37,841] {taskinstance.py:1244} INFO - Starting attempt 1 of 1
[2023-05-05 18:20:37,841] {taskinstance.py:1245} INFO - 
--------------------------------------------------------------------------------
[2023-05-05 18:20:37,848] {taskinstance.py:1264} INFO - Executing <Task(DockerOperatorWithExposedPorts): predict_service_step> on 2023-05-04 18:20:37.165834+00:00
[2023-05-05 18:20:37,851] {standard_task_runner.py:52} INFO - Started process 56953 to run task
[2023-05-05 18:20:37,853] {standard_task_runner.py:76} INFO - Running: ['***', 'tasks', 'run', 'PredictingPipeline', 'predict_service_step', 'scheduled__2023-05-04T18:20:37.165834+00:00', '--job-id', '36', '--raw', '--subdir', 'DAGS_FOLDER/predict_pipeline.py', '--cfg-path', '/tmp/tmpxf_59zf8', '--error-file', '/tmp/tmp8b_c1woe']
[2023-05-05 18:20:37,854] {standard_task_runner.py:77} INFO - Job 36: Subtask predict_service_step
[2023-05-05 18:20:37,886] {logging_mixin.py:109} INFO - Running <TaskInstance: PredictingPipeline.predict_service_step scheduled__2023-05-04T18:20:37.165834+00:00 [running]> on host bd19d9975108
[2023-05-05 18:20:37,922] {taskinstance.py:1431} INFO - Exporting the following env vars:
AIRFLOW_CTX_DAG_OWNER=***
AIRFLOW_CTX_DAG_ID=PredictingPipeline
AIRFLOW_CTX_TASK_ID=predict_service_step
AIRFLOW_CTX_EXECUTION_DATE=2023-05-04T18:20:37.165834+00:00
AIRFLOW_CTX_DAG_RUN_ID=scheduled__2023-05-04T18:20:37.165834+00:00
[2023-05-05 18:20:37,935] {docker.py:236} INFO - Starting docker container from image ml_project
[2023-05-05 18:20:37,938] {docker.py:247} WARNING - Using remote engine or docker-in-docker and mounting temporary volume from host is not supported. Falling back to `mount_tmp_dir=False` mode. You can set `mount_tmp_dir` parameter to False to disable mounting and remove the warning
[2023-05-05 18:20:37,979] {taskinstance.py:1718} ERROR - Task failed with exception
Traceback (most recent call last):
  File "/home/airflow/.local/lib/python3.7/site-packages/docker/api/client.py", line 268, in _raise_for_status
    response.raise_for_status()
  File "/home/airflow/.local/lib/python3.7/site-packages/requests/models.py", line 960, in raise_for_status
    raise HTTPError(http_error_msg, response=self)
requests.exceptions.HTTPError: 400 Client Error: Bad Request for url: http+docker://localhost/v1.42/containers/create?name=mlproject

During handling of the above exception, another exception occurred:

Traceback (most recent call last):
  File "/home/airflow/.local/lib/python3.7/site-packages/airflow/providers/docker/operators/docker.py", line 243, in _run_image
    return self._run_image_with_mounts(self.mounts + [tmp_mount], add_tmp_variable=True)
  File "/opt/airflow/plugins/operators/docker_operator_with_exposed_ports.py", line 76, in _run_image_with_mounts
    tty=self.tty,
  File "/home/airflow/.local/lib/python3.7/site-packages/docker/api/container.py", line 428, in create_container
    return self.create_container_from_config(config, name)
  File "/home/airflow/.local/lib/python3.7/site-packages/docker/api/container.py", line 439, in create_container_from_config
    return self._result(res, True)
  File "/home/airflow/.local/lib/python3.7/site-packages/docker/api/client.py", line 274, in _result
    self._raise_for_status(response)
  File "/home/airflow/.local/lib/python3.7/site-packages/docker/api/client.py", line 270, in _raise_for_status
    raise create_api_error_from_http_exception(e)
  File "/home/airflow/.local/lib/python3.7/site-packages/docker/errors.py", line 31, in create_api_error_from_http_exception
    raise cls(e, response=response, explanation=explanation)
docker.errors.APIError: 400 Client Error for http+docker://localhost/v1.42/containers/create?name=mlproject: Bad Request ("invalid mount config for type "bind": bind source path does not exist: /tmp/airflowtmpy63zuxej")

During handling of the above exception, another exception occurred:

Traceback (most recent call last):
  File "/home/airflow/.local/lib/python3.7/site-packages/docker/api/client.py", line 268, in _raise_for_status
    response.raise_for_status()
  File "/home/airflow/.local/lib/python3.7/site-packages/requests/models.py", line 960, in raise_for_status
    raise HTTPError(http_error_msg, response=self)
requests.exceptions.HTTPError: 404 Client Error: Not Found for url: http+docker://localhost/v1.42/containers/892dab5db2ebbf6cb75e410ac45e3fac08c58ed6cdc0e38be17c3f62c5a8e5d9/start

During handling of the above exception, another exception occurred:

Traceback (most recent call last):
  File "/home/airflow/.local/lib/python3.7/site-packages/airflow/models/taskinstance.py", line 1334, in _run_raw_task
    self._execute_task_with_callbacks(context)
  File "/home/airflow/.local/lib/python3.7/site-packages/airflow/models/taskinstance.py", line 1460, in _execute_task_with_callbacks
    result = self._execute_task(context, self.task)
  File "/home/airflow/.local/lib/python3.7/site-packages/airflow/models/taskinstance.py", line 1516, in _execute_task
    result = execute_callable(context=context)
  File "/home/airflow/.local/lib/python3.7/site-packages/airflow/providers/docker/operators/docker.py", line 376, in execute
    return self._run_image()
  File "/home/airflow/.local/lib/python3.7/site-packages/airflow/providers/docker/operators/docker.py", line 252, in _run_image
    return self._run_image_with_mounts(self.mounts, add_tmp_variable=False)
  File "/opt/airflow/plugins/operators/docker_operator_with_exposed_ports.py", line 87, in _run_image_with_mounts
    self.cli.start(self.container['Id'])
  File "/home/airflow/.local/lib/python3.7/site-packages/docker/utils/decorators.py", line 19, in wrapped
    return f(self, resource_id, *args, **kwargs)
  File "/home/airflow/.local/lib/python3.7/site-packages/docker/api/container.py", line 1109, in start
    self._raise_for_status(res)
  File "/home/airflow/.local/lib/python3.7/site-packages/docker/api/client.py", line 270, in _raise_for_status
    raise create_api_error_from_http_exception(e)
  File "/home/airflow/.local/lib/python3.7/site-packages/docker/errors.py", line 31, in create_api_error_from_http_exception
    raise cls(e, response=response, explanation=explanation)
docker.errors.NotFound: 404 Client Error for http+docker://localhost/v1.42/containers/892dab5db2ebbf6cb75e410ac45e3fac08c58ed6cdc0e38be17c3f62c5a8e5d9/start: Not Found ("network airflow_default not found")
[2023-05-05 18:20:37,989] {taskinstance.py:1282} INFO - Marking task as FAILED. dag_id=PredictingPipeline, task_id=predict_service_step, execution_date=20230504T182037, start_date=20230505T182037, end_date=20230505T182037
[2023-05-05 18:20:37,997] {standard_task_runner.py:92} ERROR - Failed to execute job 36 for task predict_service_step
Traceback (most recent call last):
  File "/home/airflow/.local/lib/python3.7/site-packages/docker/api/client.py", line 268, in _raise_for_status
    response.raise_for_status()
  File "/home/airflow/.local/lib/python3.7/site-packages/requests/models.py", line 960, in raise_for_status
    raise HTTPError(http_error_msg, response=self)
requests.exceptions.HTTPError: 400 Client Error: Bad Request for url: http+docker://localhost/v1.42/containers/create?name=mlproject

During handling of the above exception, another exception occurred:

Traceback (most recent call last):
  File "/home/airflow/.local/lib/python3.7/site-packages/airflow/providers/docker/operators/docker.py", line 243, in _run_image
    return self._run_image_with_mounts(self.mounts + [tmp_mount], add_tmp_variable=True)
  File "/opt/airflow/plugins/operators/docker_operator_with_exposed_ports.py", line 76, in _run_image_with_mounts
    tty=self.tty,
  File "/home/airflow/.local/lib/python3.7/site-packages/docker/api/container.py", line 428, in create_container
    return self.create_container_from_config(config, name)
  File "/home/airflow/.local/lib/python3.7/site-packages/docker/api/container.py", line 439, in create_container_from_config
    return self._result(res, True)
  File "/home/airflow/.local/lib/python3.7/site-packages/docker/api/client.py", line 274, in _result
    self._raise_for_status(response)
  File "/home/airflow/.local/lib/python3.7/site-packages/docker/api/client.py", line 270, in _raise_for_status
    raise create_api_error_from_http_exception(e)
  File "/home/airflow/.local/lib/python3.7/site-packages/docker/errors.py", line 31, in create_api_error_from_http_exception
    raise cls(e, response=response, explanation=explanation)
docker.errors.APIError: 400 Client Error for http+docker://localhost/v1.42/containers/create?name=mlproject: Bad Request ("invalid mount config for type "bind": bind source path does not exist: /tmp/airflowtmpy63zuxej")

During handling of the above exception, another exception occurred:

Traceback (most recent call last):
  File "/home/airflow/.local/lib/python3.7/site-packages/docker/api/client.py", line 268, in _raise_for_status
    response.raise_for_status()
  File "/home/airflow/.local/lib/python3.7/site-packages/requests/models.py", line 960, in raise_for_status
    raise HTTPError(http_error_msg, response=self)
requests.exceptions.HTTPError: 404 Client Error: Not Found for url: http+docker://localhost/v1.42/containers/892dab5db2ebbf6cb75e410ac45e3fac08c58ed6cdc0e38be17c3f62c5a8e5d9/start

During handling of the above exception, another exception occurred:

Traceback (most recent call last):
  File "/home/airflow/.local/lib/python3.7/site-packages/airflow/task/task_runner/standard_task_runner.py", line 85, in _start_by_fork
    args.func(args, dag=self.dag)
  File "/home/airflow/.local/lib/python3.7/site-packages/airflow/cli/cli_parser.py", line 48, in command
    return func(*args, **kwargs)
  File "/home/airflow/.local/lib/python3.7/site-packages/airflow/utils/cli.py", line 92, in wrapper
    return f(*args, **kwargs)
  File "/home/airflow/.local/lib/python3.7/site-packages/airflow/cli/commands/task_command.py", line 298, in task_run
    _run_task_by_selected_method(args, dag, ti)
  File "/home/airflow/.local/lib/python3.7/site-packages/airflow/cli/commands/task_command.py", line 107, in _run_task_by_selected_method
    _run_raw_task(args, ti)
  File "/home/airflow/.local/lib/python3.7/site-packages/airflow/cli/commands/task_command.py", line 184, in _run_raw_task
    error_file=args.error_file,
  File "/home/airflow/.local/lib/python3.7/site-packages/airflow/utils/session.py", line 70, in wrapper
    return func(*args, session=session, **kwargs)
  File "/home/airflow/.local/lib/python3.7/site-packages/airflow/models/taskinstance.py", line 1334, in _run_raw_task
    self._execute_task_with_callbacks(context)
  File "/home/airflow/.local/lib/python3.7/site-packages/airflow/models/taskinstance.py", line 1460, in _execute_task_with_callbacks
    result = self._execute_task(context, self.task)
  File "/home/airflow/.local/lib/python3.7/site-packages/airflow/models/taskinstance.py", line 1516, in _execute_task
    result = execute_callable(context=context)
  File "/home/airflow/.local/lib/python3.7/site-packages/airflow/providers/docker/operators/docker.py", line 376, in execute
    return self._run_image()
  File "/home/airflow/.local/lib/python3.7/site-packages/airflow/providers/docker/operators/docker.py", line 252, in _run_image
    return self._run_image_with_mounts(self.mounts, add_tmp_variable=False)
  File "/opt/airflow/plugins/operators/docker_operator_with_exposed_ports.py", line 87, in _run_image_with_mounts
    self.cli.start(self.container['Id'])
  File "/home/airflow/.local/lib/python3.7/site-packages/docker/utils/decorators.py", line 19, in wrapped
    return f(self, resource_id, *args, **kwargs)
  File "/home/airflow/.local/lib/python3.7/site-packages/docker/api/container.py", line 1109, in start
    self._raise_for_status(res)
  File "/home/airflow/.local/lib/python3.7/site-packages/docker/api/client.py", line 270, in _raise_for_status
    raise create_api_error_from_http_exception(e)
  File "/home/airflow/.local/lib/python3.7/site-packages/docker/errors.py", line 31, in create_api_error_from_http_exception
    raise cls(e, response=response, explanation=explanation)
docker.errors.NotFound: 404 Client Error for http+docker://localhost/v1.42/containers/892dab5db2ebbf6cb75e410ac45e3fac08c58ed6cdc0e38be17c3f62c5a8e5d9/start: Not Found ("network airflow_default not found")
[2023-05-05 18:20:38,025] {local_task_job.py:154} INFO - Task exited with return code 1
[2023-05-05 18:20:38,060] {local_task_job.py:264} INFO - 0 downstream tasks scheduled from follow-on schedule check
